{
 "cells": [
  {
   "cell_type": "code",
   "execution_count": 25,
   "metadata": {},
   "outputs": [],
   "source": [
    "\n",
    "import tensorflow as tf\n",
    "import keras\n",
    "from keras.models import Sequential\n",
    "from keras.layers import Conv2D, MaxPooling2D, Flatten, Dense, Dropout\n",
    "from sklearn.preprocessing import OneHotEncoder\n",
    "import numpy as np\n"
   ]
  },
  {
   "cell_type": "code",
   "execution_count": 36,
   "metadata": {},
   "outputs": [
    {
     "ename": "TypeError",
     "evalue": "OneHotEncoder.__init__() got an unexpected keyword argument 'sparse'",
     "output_type": "error",
     "traceback": [
      "\u001b[1;31m---------------------------------------------------------------------------\u001b[0m",
      "\u001b[1;31mTypeError\u001b[0m                                 Traceback (most recent call last)",
      "Cell \u001b[1;32mIn[36], line 7\u001b[0m\n\u001b[0;32m      4\u001b[0m \u001b[38;5;28;01mfrom\u001b[39;00m \u001b[38;5;21;01msklearn\u001b[39;00m\u001b[38;5;21;01m.\u001b[39;00m\u001b[38;5;21;01mpreprocessing\u001b[39;00m \u001b[38;5;28;01mimport\u001b[39;00m OneHotEncoder\n\u001b[0;32m      6\u001b[0m \u001b[38;5;66;03m# Define the OneHotEncoder for 26 classes\u001b[39;00m\n\u001b[1;32m----> 7\u001b[0m encoder \u001b[38;5;241m=\u001b[39m \u001b[43mOneHotEncoder\u001b[49m\u001b[43m(\u001b[49m\u001b[43msparse\u001b[49m\u001b[38;5;241;43m=\u001b[39;49m\u001b[38;5;28;43;01mFalse\u001b[39;49;00m\u001b[43m)\u001b[49m\n\u001b[0;32m      8\u001b[0m labels \u001b[38;5;241m=\u001b[39m np\u001b[38;5;241m.\u001b[39marange(\u001b[38;5;241m26\u001b[39m)\u001b[38;5;241m.\u001b[39mreshape(\u001b[38;5;241m-\u001b[39m\u001b[38;5;241m1\u001b[39m, \u001b[38;5;241m1\u001b[39m)  \u001b[38;5;66;03m# Create labels from 0 to 25 for 26 classes\u001b[39;00m\n\u001b[0;32m      9\u001b[0m encoder\u001b[38;5;241m.\u001b[39mfit(labels)\n",
      "\u001b[1;31mTypeError\u001b[0m: OneHotEncoder.__init__() got an unexpected keyword argument 'sparse'"
     ]
    }
   ],
   "source": [
    "import os\n",
    "from PIL import Image\n",
    "import numpy as np\n",
    "\n",
    "\n",
    "data=[]\n",
    "labels=[]\n",
    "\n",
    "main_dir='./data'\n",
    "for class_folder in os.listdir(main_dir):\n",
    "    class_path = os.path.join(main_dir, class_folder)\n",
    "    \n",
    "    # Ensure the item in the directory is a folder\n",
    "    if os.path.isdir(class_path):\n",
    "        # Iterate over each image file in the class folder\n",
    "        for img_file in os.listdir(class_path):\n",
    "            if img_file.endswith('.jpg') or img_file.endswith('.png'):  # Adjust file extensions as needed\n",
    "                img_path = os.path.join(class_path, img_file)\n",
    "                \n",
    "                # Open the image using PIL\n",
    "                img = Image.open(img_path)\n",
    "                img = img.resize((128,128))\n",
    "                img = np.array(img)\n",
    "                if(img.shape == (128,128,3)):\n",
    "                    data.append(np.array(img))\n",
    "                # Append the image data to the list\n",
    "                # Convert PIL image to numpy array if needed\n",
    "                \n",
    "                # Append the label (folder name) to the labels list\n",
    "                labels.append(class_folder)\n",
    "\n",
    "data = np.array(data)\n",
    "labels = np.array(labels)\n"
   ]
  },
  {
   "cell_type": "code",
   "execution_count": 14,
   "metadata": {},
   "outputs": [
    {
     "data": {
      "text/plain": [
       "(2600, 128, 128, 3)"
      ]
     },
     "execution_count": 14,
     "metadata": {},
     "output_type": "execute_result"
    }
   ],
   "source": [
    "data = np.array(data)\n",
    "data.shape"
   ]
  },
  {
   "cell_type": "code",
   "execution_count": 15,
   "metadata": {},
   "outputs": [],
   "source": [
    "from sklearn.model_selection import train_test_split\n",
    "x_train,x_test,y_train,y_test = train_test_split(data, labels, test_size=0.2, shuffle=True, random_state=0)\n",
    "     "
   ]
  },
  {
   "cell_type": "code",
   "execution_count": 21,
   "metadata": {},
   "outputs": [
    {
     "name": "stderr",
     "output_type": "stream",
     "text": [
      "c:\\Users\\samip\\AppData\\Local\\Programs\\Python\\Python310\\lib\\site-packages\\keras\\src\\layers\\convolutional\\base_conv.py:99: UserWarning: Do not pass an `input_shape`/`input_dim` argument to a layer. When using Sequential models, prefer using an `Input(shape)` object as the first layer in the model instead.\n",
      "  super().__init__(\n"
     ]
    }
   ],
   "source": [
    "# Create a Sequential model\n",
    "model = Sequential()\n",
    "\n",
    "# Add convolutional layers\n",
    "model.add(Conv2D(32, (3, 3), activation='relu', input_shape=(128, 128, 3)))\n",
    "model.add(MaxPooling2D((2, 2)))\n",
    "\n",
    "model.add(Conv2D(64, (3, 3), activation='relu'))\n",
    "model.add(MaxPooling2D((2, 2)))\n",
    "\n",
    "model.add(Conv2D(128, (3, 3), activation='relu'))\n",
    "model.add(MaxPooling2D((2, 2)))\n",
    "\n",
    "# Flatten the output and add dense layers\n",
    "model.add(Flatten())\n",
    "model.add(Dense(512, activation='relu'))\n",
    "model.add(Dropout(0.5))  # Add dropout for regularization\n",
    "model.add(Dense(128, activation='relu'))\n",
    "model.add(Dense(2, activation='softmax'))  # Output layer with 2 units (for binary classification)\n",
    "\n",
    "# Compile the model\n",
    "model.compile(optimizer='adam', loss='sparse_categorical_crossentropy', metrics=['accuracy'])\n"
   ]
  },
  {
   "cell_type": "code",
   "execution_count": 17,
   "metadata": {},
   "outputs": [],
   "source": [
    "from sklearn.preprocessing import LabelEncoder\n",
    "\n",
    "# Convert class names (folder names) to numerical labels\n",
    "label_encoder = LabelEncoder()\n",
    "y_train_encoded = label_encoder.fit_transform(y_train)"
   ]
  },
  {
   "cell_type": "code",
   "execution_count": 23,
   "metadata": {},
   "outputs": [
    {
     "name": "stdout",
     "output_type": "stream",
     "text": [
      "Epoch 1/10\n"
     ]
    },
    {
     "ename": "InvalidArgumentError",
     "evalue": "Graph execution error:\n\nDetected at node compile_loss/sparse_categorical_crossentropy/SparseSoftmaxCrossEntropyWithLogits/SparseSoftmaxCrossEntropyWithLogits defined at (most recent call last):\n  File \"c:\\Users\\samip\\AppData\\Local\\Programs\\Python\\Python310\\lib\\runpy.py\", line 196, in _run_module_as_main\n\n  File \"c:\\Users\\samip\\AppData\\Local\\Programs\\Python\\Python310\\lib\\runpy.py\", line 86, in _run_code\n\n  File \"C:\\Users\\samip\\AppData\\Roaming\\Python\\Python310\\site-packages\\ipykernel_launcher.py\", line 18, in <module>\n\n  File \"C:\\Users\\samip\\AppData\\Roaming\\Python\\Python310\\site-packages\\traitlets\\config\\application.py\", line 1075, in launch_instance\n\n  File \"C:\\Users\\samip\\AppData\\Roaming\\Python\\Python310\\site-packages\\ipykernel\\kernelapp.py\", line 739, in start\n\n  File \"C:\\Users\\samip\\AppData\\Roaming\\Python\\Python310\\site-packages\\tornado\\platform\\asyncio.py\", line 205, in start\n\n  File \"c:\\Users\\samip\\AppData\\Local\\Programs\\Python\\Python310\\lib\\asyncio\\base_events.py\", line 603, in run_forever\n\n  File \"c:\\Users\\samip\\AppData\\Local\\Programs\\Python\\Python310\\lib\\asyncio\\base_events.py\", line 1906, in _run_once\n\n  File \"c:\\Users\\samip\\AppData\\Local\\Programs\\Python\\Python310\\lib\\asyncio\\events.py\", line 80, in _run\n\n  File \"C:\\Users\\samip\\AppData\\Roaming\\Python\\Python310\\site-packages\\ipykernel\\kernelbase.py\", line 545, in dispatch_queue\n\n  File \"C:\\Users\\samip\\AppData\\Roaming\\Python\\Python310\\site-packages\\ipykernel\\kernelbase.py\", line 534, in process_one\n\n  File \"C:\\Users\\samip\\AppData\\Roaming\\Python\\Python310\\site-packages\\ipykernel\\kernelbase.py\", line 437, in dispatch_shell\n\n  File \"C:\\Users\\samip\\AppData\\Roaming\\Python\\Python310\\site-packages\\ipykernel\\ipkernel.py\", line 359, in execute_request\n\n  File \"C:\\Users\\samip\\AppData\\Roaming\\Python\\Python310\\site-packages\\ipykernel\\kernelbase.py\", line 778, in execute_request\n\n  File \"C:\\Users\\samip\\AppData\\Roaming\\Python\\Python310\\site-packages\\ipykernel\\ipkernel.py\", line 446, in do_execute\n\n  File \"C:\\Users\\samip\\AppData\\Roaming\\Python\\Python310\\site-packages\\ipykernel\\zmqshell.py\", line 549, in run_cell\n\n  File \"C:\\Users\\samip\\AppData\\Roaming\\Python\\Python310\\site-packages\\IPython\\core\\interactiveshell.py\", line 3075, in run_cell\n\n  File \"C:\\Users\\samip\\AppData\\Roaming\\Python\\Python310\\site-packages\\IPython\\core\\interactiveshell.py\", line 3130, in _run_cell\n\n  File \"C:\\Users\\samip\\AppData\\Roaming\\Python\\Python310\\site-packages\\IPython\\core\\async_helpers.py\", line 129, in _pseudo_sync_runner\n\n  File \"C:\\Users\\samip\\AppData\\Roaming\\Python\\Python310\\site-packages\\IPython\\core\\interactiveshell.py\", line 3334, in run_cell_async\n\n  File \"C:\\Users\\samip\\AppData\\Roaming\\Python\\Python310\\site-packages\\IPython\\core\\interactiveshell.py\", line 3517, in run_ast_nodes\n\n  File \"C:\\Users\\samip\\AppData\\Roaming\\Python\\Python310\\site-packages\\IPython\\core\\interactiveshell.py\", line 3577, in run_code\n\n  File \"C:\\Users\\samip\\AppData\\Local\\Temp\\ipykernel_5392\\3880151284.py\", line 1, in <module>\n\n  File \"c:\\Users\\samip\\AppData\\Local\\Programs\\Python\\Python310\\lib\\site-packages\\keras\\src\\utils\\traceback_utils.py\", line 117, in error_handler\n\n  File \"c:\\Users\\samip\\AppData\\Local\\Programs\\Python\\Python310\\lib\\site-packages\\keras\\src\\backend\\tensorflow\\trainer.py\", line 329, in fit\n\n  File \"c:\\Users\\samip\\AppData\\Local\\Programs\\Python\\Python310\\lib\\site-packages\\keras\\src\\backend\\tensorflow\\trainer.py\", line 122, in one_step_on_iterator\n\n  File \"c:\\Users\\samip\\AppData\\Local\\Programs\\Python\\Python310\\lib\\site-packages\\keras\\src\\backend\\tensorflow\\trainer.py\", line 110, in one_step_on_data\n\n  File \"c:\\Users\\samip\\AppData\\Local\\Programs\\Python\\Python310\\lib\\site-packages\\keras\\src\\backend\\tensorflow\\trainer.py\", line 60, in train_step\n\n  File \"c:\\Users\\samip\\AppData\\Local\\Programs\\Python\\Python310\\lib\\site-packages\\keras\\src\\trainers\\trainer.py\", line 323, in compute_loss\n\n  File \"c:\\Users\\samip\\AppData\\Local\\Programs\\Python\\Python310\\lib\\site-packages\\keras\\src\\trainers\\compile_utils.py\", line 605, in __call__\n\n  File \"c:\\Users\\samip\\AppData\\Local\\Programs\\Python\\Python310\\lib\\site-packages\\keras\\src\\trainers\\compile_utils.py\", line 641, in call\n\n  File \"c:\\Users\\samip\\AppData\\Local\\Programs\\Python\\Python310\\lib\\site-packages\\keras\\src\\losses\\loss.py\", line 42, in __call__\n\n  File \"c:\\Users\\samip\\AppData\\Local\\Programs\\Python\\Python310\\lib\\site-packages\\keras\\src\\losses\\losses.py\", line 22, in call\n\n  File \"c:\\Users\\samip\\AppData\\Local\\Programs\\Python\\Python310\\lib\\site-packages\\keras\\src\\losses\\losses.py\", line 1714, in sparse_categorical_crossentropy\n\n  File \"c:\\Users\\samip\\AppData\\Local\\Programs\\Python\\Python310\\lib\\site-packages\\keras\\src\\ops\\nn.py\", line 1567, in sparse_categorical_crossentropy\n\n  File \"c:\\Users\\samip\\AppData\\Local\\Programs\\Python\\Python310\\lib\\site-packages\\keras\\src\\backend\\tensorflow\\nn.py\", line 659, in sparse_categorical_crossentropy\n\nReceived a label value of 25 which is outside the valid range of [0, 2).  Label values: 19 24 8 2 4 25 7 11 16 25 17 16 10 3 23 3 4 2 8 15 24 10 18 11 8 9 17 12 0 4 10 6\n\t [[{{node compile_loss/sparse_categorical_crossentropy/SparseSoftmaxCrossEntropyWithLogits/SparseSoftmaxCrossEntropyWithLogits}}]] [Op:__inference_one_step_on_iterator_3455]",
     "output_type": "error",
     "traceback": [
      "\u001b[1;31m---------------------------------------------------------------------------\u001b[0m",
      "\u001b[1;31mInvalidArgumentError\u001b[0m                      Traceback (most recent call last)",
      "Cell \u001b[1;32mIn[23], line 1\u001b[0m\n\u001b[1;32m----> 1\u001b[0m history \u001b[38;5;241m=\u001b[39m \u001b[43mmodel\u001b[49m\u001b[38;5;241;43m.\u001b[39;49m\u001b[43mfit\u001b[49m\u001b[43m(\u001b[49m\u001b[43mx_train\u001b[49m\u001b[43m,\u001b[49m\u001b[43m \u001b[49m\u001b[43my_train_encoded\u001b[49m\u001b[43m,\u001b[49m\u001b[43m \u001b[49m\u001b[43mepochs\u001b[49m\u001b[38;5;241;43m=\u001b[39;49m\u001b[38;5;241;43m10\u001b[39;49m\u001b[43m,\u001b[49m\u001b[43m \u001b[49m\u001b[43mbatch_size\u001b[49m\u001b[38;5;241;43m=\u001b[39;49m\u001b[38;5;241;43m32\u001b[39;49m\u001b[43m,\u001b[49m\u001b[43m \u001b[49m\u001b[43mvalidation_split\u001b[49m\u001b[38;5;241;43m=\u001b[39;49m\u001b[38;5;241;43m0.2\u001b[39;49m\u001b[43m)\u001b[49m\n",
      "File \u001b[1;32mc:\\Users\\samip\\AppData\\Local\\Programs\\Python\\Python310\\lib\\site-packages\\keras\\src\\utils\\traceback_utils.py:122\u001b[0m, in \u001b[0;36mfilter_traceback.<locals>.error_handler\u001b[1;34m(*args, **kwargs)\u001b[0m\n\u001b[0;32m    119\u001b[0m     filtered_tb \u001b[38;5;241m=\u001b[39m _process_traceback_frames(e\u001b[38;5;241m.\u001b[39m__traceback__)\n\u001b[0;32m    120\u001b[0m     \u001b[38;5;66;03m# To get the full stack trace, call:\u001b[39;00m\n\u001b[0;32m    121\u001b[0m     \u001b[38;5;66;03m# `keras.config.disable_traceback_filtering()`\u001b[39;00m\n\u001b[1;32m--> 122\u001b[0m     \u001b[38;5;28;01mraise\u001b[39;00m e\u001b[38;5;241m.\u001b[39mwith_traceback(filtered_tb) \u001b[38;5;28;01mfrom\u001b[39;00m \u001b[38;5;28;01mNone\u001b[39;00m\n\u001b[0;32m    123\u001b[0m \u001b[38;5;28;01mfinally\u001b[39;00m:\n\u001b[0;32m    124\u001b[0m     \u001b[38;5;28;01mdel\u001b[39;00m filtered_tb\n",
      "File \u001b[1;32mc:\\Users\\samip\\AppData\\Local\\Programs\\Python\\Python310\\lib\\site-packages\\tensorflow\\python\\eager\\execute.py:53\u001b[0m, in \u001b[0;36mquick_execute\u001b[1;34m(op_name, num_outputs, inputs, attrs, ctx, name)\u001b[0m\n\u001b[0;32m     51\u001b[0m \u001b[38;5;28;01mtry\u001b[39;00m:\n\u001b[0;32m     52\u001b[0m   ctx\u001b[38;5;241m.\u001b[39mensure_initialized()\n\u001b[1;32m---> 53\u001b[0m   tensors \u001b[38;5;241m=\u001b[39m pywrap_tfe\u001b[38;5;241m.\u001b[39mTFE_Py_Execute(ctx\u001b[38;5;241m.\u001b[39m_handle, device_name, op_name,\n\u001b[0;32m     54\u001b[0m                                       inputs, attrs, num_outputs)\n\u001b[0;32m     55\u001b[0m \u001b[38;5;28;01mexcept\u001b[39;00m core\u001b[38;5;241m.\u001b[39m_NotOkStatusException \u001b[38;5;28;01mas\u001b[39;00m e:\n\u001b[0;32m     56\u001b[0m   \u001b[38;5;28;01mif\u001b[39;00m name \u001b[38;5;129;01mis\u001b[39;00m \u001b[38;5;129;01mnot\u001b[39;00m \u001b[38;5;28;01mNone\u001b[39;00m:\n",
      "\u001b[1;31mInvalidArgumentError\u001b[0m: Graph execution error:\n\nDetected at node compile_loss/sparse_categorical_crossentropy/SparseSoftmaxCrossEntropyWithLogits/SparseSoftmaxCrossEntropyWithLogits defined at (most recent call last):\n  File \"c:\\Users\\samip\\AppData\\Local\\Programs\\Python\\Python310\\lib\\runpy.py\", line 196, in _run_module_as_main\n\n  File \"c:\\Users\\samip\\AppData\\Local\\Programs\\Python\\Python310\\lib\\runpy.py\", line 86, in _run_code\n\n  File \"C:\\Users\\samip\\AppData\\Roaming\\Python\\Python310\\site-packages\\ipykernel_launcher.py\", line 18, in <module>\n\n  File \"C:\\Users\\samip\\AppData\\Roaming\\Python\\Python310\\site-packages\\traitlets\\config\\application.py\", line 1075, in launch_instance\n\n  File \"C:\\Users\\samip\\AppData\\Roaming\\Python\\Python310\\site-packages\\ipykernel\\kernelapp.py\", line 739, in start\n\n  File \"C:\\Users\\samip\\AppData\\Roaming\\Python\\Python310\\site-packages\\tornado\\platform\\asyncio.py\", line 205, in start\n\n  File \"c:\\Users\\samip\\AppData\\Local\\Programs\\Python\\Python310\\lib\\asyncio\\base_events.py\", line 603, in run_forever\n\n  File \"c:\\Users\\samip\\AppData\\Local\\Programs\\Python\\Python310\\lib\\asyncio\\base_events.py\", line 1906, in _run_once\n\n  File \"c:\\Users\\samip\\AppData\\Local\\Programs\\Python\\Python310\\lib\\asyncio\\events.py\", line 80, in _run\n\n  File \"C:\\Users\\samip\\AppData\\Roaming\\Python\\Python310\\site-packages\\ipykernel\\kernelbase.py\", line 545, in dispatch_queue\n\n  File \"C:\\Users\\samip\\AppData\\Roaming\\Python\\Python310\\site-packages\\ipykernel\\kernelbase.py\", line 534, in process_one\n\n  File \"C:\\Users\\samip\\AppData\\Roaming\\Python\\Python310\\site-packages\\ipykernel\\kernelbase.py\", line 437, in dispatch_shell\n\n  File \"C:\\Users\\samip\\AppData\\Roaming\\Python\\Python310\\site-packages\\ipykernel\\ipkernel.py\", line 359, in execute_request\n\n  File \"C:\\Users\\samip\\AppData\\Roaming\\Python\\Python310\\site-packages\\ipykernel\\kernelbase.py\", line 778, in execute_request\n\n  File \"C:\\Users\\samip\\AppData\\Roaming\\Python\\Python310\\site-packages\\ipykernel\\ipkernel.py\", line 446, in do_execute\n\n  File \"C:\\Users\\samip\\AppData\\Roaming\\Python\\Python310\\site-packages\\ipykernel\\zmqshell.py\", line 549, in run_cell\n\n  File \"C:\\Users\\samip\\AppData\\Roaming\\Python\\Python310\\site-packages\\IPython\\core\\interactiveshell.py\", line 3075, in run_cell\n\n  File \"C:\\Users\\samip\\AppData\\Roaming\\Python\\Python310\\site-packages\\IPython\\core\\interactiveshell.py\", line 3130, in _run_cell\n\n  File \"C:\\Users\\samip\\AppData\\Roaming\\Python\\Python310\\site-packages\\IPython\\core\\async_helpers.py\", line 129, in _pseudo_sync_runner\n\n  File \"C:\\Users\\samip\\AppData\\Roaming\\Python\\Python310\\site-packages\\IPython\\core\\interactiveshell.py\", line 3334, in run_cell_async\n\n  File \"C:\\Users\\samip\\AppData\\Roaming\\Python\\Python310\\site-packages\\IPython\\core\\interactiveshell.py\", line 3517, in run_ast_nodes\n\n  File \"C:\\Users\\samip\\AppData\\Roaming\\Python\\Python310\\site-packages\\IPython\\core\\interactiveshell.py\", line 3577, in run_code\n\n  File \"C:\\Users\\samip\\AppData\\Local\\Temp\\ipykernel_5392\\3880151284.py\", line 1, in <module>\n\n  File \"c:\\Users\\samip\\AppData\\Local\\Programs\\Python\\Python310\\lib\\site-packages\\keras\\src\\utils\\traceback_utils.py\", line 117, in error_handler\n\n  File \"c:\\Users\\samip\\AppData\\Local\\Programs\\Python\\Python310\\lib\\site-packages\\keras\\src\\backend\\tensorflow\\trainer.py\", line 329, in fit\n\n  File \"c:\\Users\\samip\\AppData\\Local\\Programs\\Python\\Python310\\lib\\site-packages\\keras\\src\\backend\\tensorflow\\trainer.py\", line 122, in one_step_on_iterator\n\n  File \"c:\\Users\\samip\\AppData\\Local\\Programs\\Python\\Python310\\lib\\site-packages\\keras\\src\\backend\\tensorflow\\trainer.py\", line 110, in one_step_on_data\n\n  File \"c:\\Users\\samip\\AppData\\Local\\Programs\\Python\\Python310\\lib\\site-packages\\keras\\src\\backend\\tensorflow\\trainer.py\", line 60, in train_step\n\n  File \"c:\\Users\\samip\\AppData\\Local\\Programs\\Python\\Python310\\lib\\site-packages\\keras\\src\\trainers\\trainer.py\", line 323, in compute_loss\n\n  File \"c:\\Users\\samip\\AppData\\Local\\Programs\\Python\\Python310\\lib\\site-packages\\keras\\src\\trainers\\compile_utils.py\", line 605, in __call__\n\n  File \"c:\\Users\\samip\\AppData\\Local\\Programs\\Python\\Python310\\lib\\site-packages\\keras\\src\\trainers\\compile_utils.py\", line 641, in call\n\n  File \"c:\\Users\\samip\\AppData\\Local\\Programs\\Python\\Python310\\lib\\site-packages\\keras\\src\\losses\\loss.py\", line 42, in __call__\n\n  File \"c:\\Users\\samip\\AppData\\Local\\Programs\\Python\\Python310\\lib\\site-packages\\keras\\src\\losses\\losses.py\", line 22, in call\n\n  File \"c:\\Users\\samip\\AppData\\Local\\Programs\\Python\\Python310\\lib\\site-packages\\keras\\src\\losses\\losses.py\", line 1714, in sparse_categorical_crossentropy\n\n  File \"c:\\Users\\samip\\AppData\\Local\\Programs\\Python\\Python310\\lib\\site-packages\\keras\\src\\ops\\nn.py\", line 1567, in sparse_categorical_crossentropy\n\n  File \"c:\\Users\\samip\\AppData\\Local\\Programs\\Python\\Python310\\lib\\site-packages\\keras\\src\\backend\\tensorflow\\nn.py\", line 659, in sparse_categorical_crossentropy\n\nReceived a label value of 25 which is outside the valid range of [0, 2).  Label values: 19 24 8 2 4 25 7 11 16 25 17 16 10 3 23 3 4 2 8 15 24 10 18 11 8 9 17 12 0 4 10 6\n\t [[{{node compile_loss/sparse_categorical_crossentropy/SparseSoftmaxCrossEntropyWithLogits/SparseSoftmaxCrossEntropyWithLogits}}]] [Op:__inference_one_step_on_iterator_3455]"
     ]
    }
   ],
   "source": [
    "\n",
    "history = model.fit(x_train, y_train_encoded, epochs=10, batch_size=32, validation_split=0.2)\n",
    "\n",
    "     "
   ]
  }
 ],
 "metadata": {
  "kernelspec": {
   "display_name": "Python 3",
   "language": "python",
   "name": "python3"
  },
  "language_info": {
   "codemirror_mode": {
    "name": "ipython",
    "version": 3
   },
   "file_extension": ".py",
   "mimetype": "text/x-python",
   "name": "python",
   "nbconvert_exporter": "python",
   "pygments_lexer": "ipython3",
   "version": "3.10.9"
  }
 },
 "nbformat": 4,
 "nbformat_minor": 2
}
